<?xml version="1.0" encoding="utf-8"?>
<!--
  TurtleBot3 Burger URDF for NVIDIA Isaac Sim
  - Optimized for differential drive
  - LiDAR (LDS-01) included
  - Jetson Orin Nano mount included
  - Camera mount included
-->
<robot name="turtlebot3_burger">

  <!-- Materials -->
  <material name="light_black">
    <color rgba="0.3 0.3 0.3 1.0"/>
  </material>
  <material name="dark">
    <color rgba="0.1 0.1 0.1 1.0"/>
  </material>
  <material name="white">
    <color rgba="1.0 1.0 1.0 1.0"/>
  </material>
  <material name="red">
    <color rgba="1.0 0.0 0.0 1.0"/>
  </material>
  <material name="blue">
    <color rgba="0.0 0.0 1.0 1.0"/>
  </material>

  <!-- ============== Base Link ============== -->
  <link name="base_link">
    <visual>
      <origin rpy="0 0 0" xyz="-0.032 0 0.0"/>
      <geometry>
        <mesh filename="meshes/burger_base.stl" scale="0.001 0.001 0.001"/>
      </geometry>
      <material name="light_black"/>
    </visual>
    <collision>
      <origin rpy="0 0 0" xyz="-0.032 0 0.070"/>
      <geometry>
        <box size="0.140 0.140 0.143"/>
      </geometry>
    </collision>
    <inertial>
      <origin rpy="0 0 0" xyz="0 0 0"/>
      <mass value="0.8257"/>
      <inertia ixx="0.002212" ixy="-0.000012" ixz="0.000035"
               iyy="0.002119" iyz="-0.000005" izz="0.002006"/>
    </inertial>
  </link>

  <!-- ============== Left Wheel ============== -->
  <joint name="wheel_left_joint" type="continuous">
    <parent link="base_link"/>
    <child link="wheel_left_link"/>
    <origin rpy="-1.57 0 0" xyz="0.0 0.080 0.023"/>
    <axis xyz="0 0 1"/>
    <limit effort="1.0" velocity="10.0"/>
    <dynamics damping="0.001" friction="0.001"/>
  </joint>
  <link name="wheel_left_link">
    <visual>
      <origin rpy="1.57 0 0" xyz="0 0 0"/>
      <geometry>
        <mesh filename="meshes/left_tire.stl" scale="0.001 0.001 0.001"/>
      </geometry>
      <material name="dark"/>
    </visual>
    <collision>
      <origin rpy="0 0 0" xyz="0 0 0"/>
      <geometry>
        <cylinder length="0.018" radius="0.033"/>
      </geometry>
    </collision>
    <inertial>
      <origin xyz="0 0 0"/>
      <mass value="0.0285"/>
      <inertia ixx="0.000011" ixy="0.0" ixz="0.0"
               iyy="0.000011" iyz="0.0" izz="0.000021"/>
    </inertial>
  </link>

  <!-- ============== Right Wheel ============== -->
  <joint name="wheel_right_joint" type="continuous">
    <parent link="base_link"/>
    <child link="wheel_right_link"/>
    <origin rpy="-1.57 0 0" xyz="0.0 -0.080 0.023"/>
    <axis xyz="0 0 1"/>
    <limit effort="1.0" velocity="10.0"/>
    <dynamics damping="0.001" friction="0.001"/>
  </joint>
  <link name="wheel_right_link">
    <visual>
      <origin rpy="1.57 0 0" xyz="0 0 0"/>
      <geometry>
        <mesh filename="meshes/right_tire.stl" scale="0.001 0.001 0.001"/>
      </geometry>
      <material name="dark"/>
    </visual>
    <collision>
      <origin rpy="0 0 0" xyz="0 0 0"/>
      <geometry>
        <cylinder length="0.018" radius="0.033"/>
      </geometry>
    </collision>
    <inertial>
      <origin xyz="0 0 0"/>
      <mass value="0.0285"/>
      <inertia ixx="0.000011" ixy="0.0" ixz="0.0"
               iyy="0.000011" iyz="0.0" izz="0.000021"/>
    </inertial>
  </link>

  <!-- ============== Caster Back ============== -->
  <joint name="caster_back_joint" type="fixed">
    <parent link="base_link"/>
    <child link="caster_back_link"/>
    <origin rpy="-1.57 0 0" xyz="-0.081 0 -0.004"/>
  </joint>
  <link name="caster_back_link">
    <collision>
      <origin rpy="0 0 0" xyz="0 0 0"/>
      <geometry>
        <sphere radius="0.014"/>
      </geometry>
    </collision>
    <inertial>
      <origin xyz="0 0 0"/>
      <mass value="0.001"/>
      <inertia ixx="0.000001" ixy="0.0" ixz="0.0"
               iyy="0.000001" iyz="0.0" izz="0.000001"/>
    </inertial>
  </link>

  <!-- ============== LiDAR (LDS-01) ============== -->
  <joint name="base_scan_joint" type="fixed">
    <parent link="base_link"/>
    <child link="base_scan"/>
    <origin rpy="0 0 0" xyz="-0.032 0 0.077"/>
  </joint>
  <link name="base_scan">
    <visual>
      <origin rpy="0 0 0" xyz="0 0 0"/>
      <geometry>
        <mesh filename="meshes/lds.stl" scale="0.001 0.001 0.001"/>
      </geometry>
      <material name="dark"/>
    </visual>
    <collision>
      <origin rpy="0 0 0" xyz="0 0 0"/>
      <geometry>
        <cylinder length="0.030" radius="0.036"/>
      </geometry>
    </collision>
    <inertial>
      <origin xyz="0 0 0"/>
      <mass value="0.010"/>
      <inertia ixx="0.000001" ixy="0.0" ixz="0.0"
               iyy="0.000001" iyz="0.0" izz="0.000001"/>
    </inertial>
  </link>

  <!-- ============== IMU ============== -->
  <joint name="imu_joint" type="fixed">
    <parent link="base_link"/>
    <child link="imu_link"/>
    <origin rpy="0 0 0" xyz="0 0 0"/>
  </joint>
  <link name="imu_link">
    <inertial>
      <origin xyz="0 0 0"/>
      <mass value="0.005"/>
      <inertia ixx="0.000001" ixy="0.0" ixz="0.0"
               iyy="0.000001" iyz="0.0" izz="0.000001"/>
    </inertial>
  </link>

  <!-- ============== Plate (Top Plate) ============== -->
  <joint name="plate_joint" type="fixed">
    <parent link="base_link"/>
    <child link="plate_link"/>
    <origin rpy="0 0 0" xyz="-0.032 0 0.070"/>
  </joint>
  <link name="plate_link">
    <visual>
      <origin rpy="0 0 0" xyz="0 0 0"/>
      <geometry>
        <mesh filename="meshes/burger_plate.stl" scale="0.001 0.001 0.001"/>
      </geometry>
      <material name="white"/>
    </visual>
  </link>

  <!-- ============== Jetson Orin Nano (Robot 1 only) ============== -->
  <joint name="jetson_joint" type="fixed">
    <parent link="plate_link"/>
    <child link="jetson_link"/>
    <origin rpy="0 0 0" xyz="0.0 0.0 0.020"/>
  </joint>
  <link name="jetson_link">
    <visual>
      <origin rpy="0 0 0" xyz="0 0 0"/>
      <geometry>
        <box size="0.100 0.080 0.020"/>
      </geometry>
      <material name="red"/>
    </visual>
    <collision>
      <origin rpy="0 0 0" xyz="0 0 0"/>
      <geometry>
        <box size="0.100 0.080 0.020"/>
      </geometry>
    </collision>
    <inertial>
      <origin xyz="0 0 0"/>
      <mass value="0.250"/>
      <inertia ixx="0.0003" ixy="0.0" ixz="0.0"
               iyy="0.0003" iyz="0.0" izz="0.0001"/>
    </inertial>
  </link>

  <!-- ============== Camera (Front) ============== -->
  <joint name="camera_joint" type="fixed">
    <parent link="base_link"/>
    <child link="camera_link"/>
    <origin rpy="0 0 0" xyz="0.040 0 0.060"/>
  </joint>
  <link name="camera_link">
    <visual>
      <origin rpy="0 0 0" xyz="0 0 0"/>
      <geometry>
        <box size="0.025 0.020 0.020"/>
      </geometry>
      <material name="blue"/>
    </visual>
    <collision>
      <origin rpy="0 0 0" xyz="0 0 0"/>
      <geometry>
        <box size="0.025 0.020 0.020"/>
      </geometry>
    </collision>
    <inertial>
      <origin xyz="0 0 0"/>
      <mass value="0.005"/>
      <inertia ixx="0.000001" ixy="0.0" ixz="0.0"
               iyy="0.000001" iyz="0.0" izz="0.000001"/>
    </inertial>
  </link>

  <!-- ============== ROS2 Control ============== -->
  <ros2_control name="TurtleBot3Control" type="system">
    <hardware>
      <plugin>gazebo_ros2_control/GazeboSystem</plugin>
    </hardware>
    <joint name="wheel_left_joint">
      <command_interface name="velocity"/>
      <state_interface name="position"/>
      <state_interface name="velocity"/>
      <state_interface name="effort"/>
    </joint>
    <joint name="wheel_right_joint">
      <command_interface name="velocity"/>
      <state_interface name="position"/>
      <state_interface name="velocity"/>
      <state_interface name="effort"/>
    </joint>
  </ros2_control>

  <!-- Gazebo Plugin (for Gazebo compatibility) -->
  <gazebo>
    <plugin name="gazebo_ros2_control" filename="libgazebo_ros2_control.so">
      <parameters>$(find turtlebot3_description)/config/turtlebot3_ros2_control.yaml</parameters>
    </plugin>
  </gazebo>

</robot>
